Workbook

Sheet JAN25
A1: Date | B1: Actual | C1: Budget | D1: Actual Cumm | E1: Budget Cumm | F1: FOOD | G1: Other
A2: 45658 | B2: ='JAN25'!$F2+'JAN25'!$G2 -> 130 | C2: 150 | D2: =B2 -> 130 | E2: =C2 -> 150 | F2: 110 | G2: 20 | I2: Gold | J2: 300
A3: 45659 | B3: ='JAN25'!$F3+'JAN25'!$G3 -> 80 | C3: 150 | D3: =D2+B3 -> 210 | E3: =C3+C2 -> 300 | F3: 80 | I3: SIP | J3: 2000 | L3: AC Bal(1st Jan) | M3: 44780
A4: 45660 | B4: ='JAN25'!$F4+'JAN25'!$G4 -> 100 | C4: 150 | D4: =D3+B4 -> 310 | E4: =C4+E3 -> 450 | F4: 100 | I4: Rent | J4: 7000 | M4: =SUM(J2:J9) -> 18710 | R4: =J2+J3+J5+J6+J7+J9+J10 -> 9310
A5: 45661 | B5: ='JAN25'!$F5+'JAN25'!$G5 -> 78 | C5: 150 | D5: =D4+B5 -> 388 | E5: =E4+150 -> 600 | F5: =25+25 -> 50 | G5: 28 | I5: Expenses | J5: =D32 -> 2590
A6: 45662 | B6: ='JAN25'!$F6+'JAN25'!$G6 -> 182 | C6: 150 | D6: =D5+B6 -> 570 | E6: =E5+150 -> 750 | F6: 150 | G6: 32 | I6: Travel | J6: =1200+1500 -> 2700
A7: 45663 | B7: ='JAN25'!$F7+'JAN25'!$G7 -> 60 | C7: 150 | D7: =D6+B7 -> 630 | E7: =E6+150 -> 900 | F7: 60 | I7: Medical | J7: 500
A8: 45664 | B8: ='JAN25'!$F8+'JAN25'!$G8 -> 237 | C8: 150 | D8: =D7+B8 -> 867 | E8: =E7+150 -> 1050 | F8: =24+35 -> 59 | G8: 178 | I8: Stocks | J8: 3000
A9: 45665 | B9: ='JAN25'!$F9+'JAN25'!$G9 -> 40 | C9: 150 | D9: =D8+B9 -> 907 | E9: =E8+150 -> 1200 | F9: =20+20 -> 40 | I9: Recharge | J9: 620
A10: 45666 | B10: ='JAN25'!$F10+'JAN25'!$G10 -> 72 | C10: 150 | D10: =D9+B10 -> 979 | E10: =E9+150 -> 1350 | F10: =12+35+25 -> 72 | I10: GYM | J10: 600
A11: 45667 | B11: ='JAN25'!$F11+'JAN25'!$G11 -> 212 | C11: 150 | D11: =D10+B11 -> 1191 | E11: =E10+150 -> 1500 | F11: 200 | G11: 12 | I11: MF | J11: 500
A12: 45668 | B12: ='JAN25'!$F12+'JAN25'!$G12 -> 75 | C12: 150 | D12: =D11+B12 -> 1266 | E12: =E11+150 -> 1650 | G12: 75
A13: 45669 | B13: ='JAN25'!$F13+'JAN25'!$G13 -> 0 | C13: 150 | D13: =D12+B13 -> 1266 | E13: =E12+150 -> 1800
A14: 45670 | B14: ='JAN25'!$F14+'JAN25'!$G14 -> 33 | C14: 150 | D14: =D13+B14 -> 1299 | E14: =E13+150 -> 1950 | G14: 33
A15: 45671 | B15: ='JAN25'!$F15+'JAN25'!$G15 -> 0 | C15: 150 | D15: =D14+B15 -> 1299 | E15: =E14+150 -> 2100
A16: 45672 | B16: ='JAN25'!$F16+'JAN25'!$G16 -> 33 | C16: 150 | D16: =D15+B16 -> 1332 | E16: =E15+150 -> 2250 | G16: 33
A17: 45673 | B17: ='JAN25'!$F17+'JAN25'!$G17 -> 71 | C17: 150 | D17: =D16+B17 -> 1403 | E17: =E16+150 -> 2400 | G17: 71
A18: 45674 | B18: ='JAN25'!$F18+'JAN25'!$G18 -> 12 | C18: 150 | D18: =D17+B18 -> 1415 | E18: =E17+150 -> 2550 | F18: 12
A19: 45675 | B19: ='JAN25'!$F19+'JAN25'!$G19 -> 178 | C19: 150 | D19: =D18+B19 -> 1593 | E19: =E18+150 -> 2700 | F19: 150 | G19: 28
A20: 45676 | B20: ='JAN25'!$F20+'JAN25'!$G20 -> 45 | C20: 150 | D20: =D19+B20 -> 1638 | E20: =E19+150 -> 2850 | F20: 45
A21: 45677 | B21: ='JAN25'!$F21+'JAN25'!$G21 -> 110 | C21: 150 | D21: =D20+B21 -> 1748 | E21: =E20+150 -> 3000 | F21: 60 | G21: 50
A22: 45678 | B22: ='JAN25'!$F22+'JAN25'!$G22 -> 45 | C22: 150 | D22: =D21+B22 -> 1793 | E22: =E21+150 -> 3150 | F22: 45
A23: 45679 | B23: ='JAN25'!$F23+'JAN25'!$G23 -> 32 | C23: 150 | D23: =D22+B23 -> 1825 | E23: =E22+150 -> 3300 | F23: =12+20 -> 32
A24: 45680 | B24: ='JAN25'!$F24+'JAN25'!$G24 -> 0 | C24: 150 | D24: =D23+B24 -> 1825 | E24: =E23+150 -> 3450 | F24: 0
A25: 45681 | B25: ='JAN25'!$F25+'JAN25'!$G25 -> 152 | C25: 150 | D25: =D24+B25 -> 1977 | E25: =E24+150 -> 3600 | F25: 12 | G25: 140
A26: 45682 | B26: ='JAN25'!$F26+'JAN25'!$G26 -> 69 | C26: 150 | D26: =D25+B26 -> 2046 | E26: =E25+150 -> 3750 | F26: =57+12 -> 69 | S26: =Q26*R26 -> 0
A27: 45683 | B27: ='JAN25'!$F27+'JAN25'!$G27 -> 160 | C27: 150 | D27: =D26+B27 -> 2206 | E27: =E26+150 -> 3900 | F27: 40 | G27: =120 -> 120
A28: 45684 | B28: ='JAN25'!$F28+'JAN25'!$G28 -> 32 | C28: 150 | D28: =D27+B28 -> 2238 | E28: =E27+150 -> 4050 | F28: =20+12 -> 32 | S28: =S27+U27 -> 0
A29: 45685 | B29: ='JAN25'!$F29+'JAN25'!$G29 -> 80 | C29: 150 | D29: =D28+B29 -> 2318 | E29: =E28+150 -> 4200 | F29: =80 -> 80
A30: 45686 | B30: ='JAN25'!$F30+'JAN25'!$G30 -> 20 | C30: 150 | D30: =D29+B30 -> 2338 | E30: =E29+150 -> 4350 | F30: 20
A31: 45687 | B31: ='JAN25'!$F31+'JAN25'!$G31 -> 90 | C31: 150 | D31: =D30+B31 -> 2428 | E31: =E30+150 -> 4500 | F31: 90
A32: 45688 | B32: ='JAN25'!$F32+'JAN25'!$G32 -> 162 | C32: 150 | D32: =D31+B32 -> 2590 | E32: =E31+150 -> 4650 | F32: =12+100+50 -> 162
A33: 45689 | B33: ='JAN25'!$F33+'JAN25'!$G33 -> 48 | C33: 150 | D33: ='JAN25'!$B33 -> 48 | E33: ='JAN25'!$C33 -> 150 | F33: 48 | I33: Gold | J33: 300 | L33: AC Bal(1st Feb) | M33: 44397
A34: 45690 | B34: ='JAN25'!$F34+'JAN25'!$G34 -> 114 | C34: 150 | D34: ='JAN25'!$B34+D33 -> 162 | E34: =E33+'JAN25'!$C34 -> 300 | F34: =65 -> 65 | G34: =23+26 -> 49 | I34: SIP | J34: 2000 | M34: =SUM(J33:J39) -> 13937
A35: 45691 | B35: ='JAN25'!$F35+'JAN25'!$G35 -> 55 | C35: 150 | D35: ='JAN25'!$B35+D34 -> 217 | E35: =E34+'JAN25'!$C35 -> 450 | F35: 55 | I35: ETF | J35: 500
A36: 45692 | B36: ='JAN25'!$F36+'JAN25'!$G36 -> 162 | C36: 150 | D36: ='JAN25'!$B36+D35 -> 379 | E36: =E35+'JAN25'!$C36 -> 600 | F36: =140+22 -> 162 | I36: Expenses | J36: =D60 -> 2737 | M36: =10000 -> 10000
A37: 45693 | B37: ='JAN25'!$F37+'JAN25'!$G37 -> 184 | C37: 150 | D37: ='JAN25'!$B37+D36 -> 563 | E37: =E36+'JAN25'!$C37 -> 750 | F37: =160+24 -> 184 | I37: GYM | J37: 600
A38: 45694 | B38: ='JAN25'!$F38+'JAN25'!$G38 -> 118 | C38: 150 | D38: ='JAN25'!$B38+D37 -> 681 | E38: =E37+'JAN25'!$C38 -> 900 | F38: =50+10+25+33 -> 118 | I38: Rent | J38: 7000
A39: 45695 | B39: ='JAN25'!$F39+'JAN25'!$G39 -> 12 | C39: 150 | D39: ='JAN25'!$B39+D38 -> 693 | E39: =E38+'JAN25'!$C39 -> 1050 | F39: 12 | I39: Airpods | J39: 800
A40: 45696 | B40: ='JAN25'!$F40+'JAN25'!$G40 -> 49 | C40: 150 | D40: ='JAN25'!$B40+D39 -> 742 | E40: =E39+'JAN25'!$C40 -> 1200 | F40: =14+10+25 -> 49 | I40: MF | J40: 500
...

Sheet Pivot Table 1

Sheet SQL30(learning with jelly)
A1: Day | B1: Topics
A2: 45839
A3: 45840
A4: 45841
A5: 45842
A6: 45843
A7: 45844
A8: 45845 | B8: create tables
A9: 45846 | B9: where,and,or,comparision(=,<>,!=,<=) | C9: in | D9: like(%),(_)
A10: 45847 | B10: order by
A11: 45848 | B11: update,delete,alter,drop
A12: 45849 | B12: aggregate functions | C12: sum,count,avg
A13: 45850 | B13: group by,having
A14: 45851 | B14: case study
A15: 45852 | B15: left,inner,right joins
A16: 45853 | B16: full outer,union all, union(remove duplicates),self | C16: join 3 or more tables
A17: 45854 | B17: CTES SUBQUERIES
A18: 45855 | B18: PRACTICE OF 14&15
A19: 45856 | B19: SET OPEARATORS | C19: UNION,UNIONALL,INTERSECT(INNER),EXCEPT(RETURN ROWS ONLY FROM FIRST TABLE that are not in 2 nd table)
A20: 45857 | B20: CTES
A21: 45858 | B21: practice ctes in website
A22: 45859 | B22: window functions | C22: over,partition by,row number
A23: 45860 | B23: Rank(skips the number) | C23: dense_rank(dont skip) | D23: lag
A24: 45861 | B24: String functions(length,upper,lower,substr,trim)
A25: 45862 | B25: practice(Windows,string functions)
A26: 45863 | B26: Case when statements
A27: 45864 | B27: Other functions(Coalesce,replace,date,strftime('%y-%m-%d),round(total,2) | C27: select firstname,lastname,replace(email,'@example.com','domain.com') from customers
A28: 45865 | B28: Mini project | C28: 1.what is average invoice total by customer.
B29: Mini project | C29: 2.what are the top 10 customers with most invoices.
B30: Mini project | C30: 3.what are top 10 customers by purchase amount
B31: Mini project | C31: 4.what are total sales by country
A32: 45866 | B32: Mini project-2 | C32: 1.use a cte and calculate total sales for year 2012. Include the month and total sales amount
C33: 2.calculate running total o sales for each customer include the customername,invoicedate,invoice total & running total (hind use window function)
C34: 3.Identify the highest spending customer in each country (include country,customername,total speding)
A35: 45867 | B35: Showcasing SQL work
A36: 45868 | B36: Final recap

Sheet Diet
A1: Date | B1: Breakfast | C1: Mid Morning snack | D1: Lunch | E1: Evening snacks | F1: Dinner | G1: Before Bed
A2: 45693 | B2: Eggs | C2: Nuts, froot smoothie | E2: Fruits, | G2: Milk,nuts
A3: 45694 | B3: to
A4: 45695
A5: 45696
A6: 45697
A7: 45698
A8: 45699
A9: 45700
A10: 45701
A11: 45702
A12: 45703
A13: 45704
A14: 45705
A17: To-do
A18: Mon | B18: Breakfast | D18: Lunch | F18: Snack | G18: Dinner

Sheet Consolidated_Exp
A1: Date | B1: Category | C1: Amount
A2: 45292 | B2: Rent | C2: 8000
A3: 45292 | B3: SIP | C3: 2000
A4: 45292 | B4: STOCKS | C4: 2000
A5: 45292 | B5: Travel | C5: 5000
A6: 45292 | B6: Expenses | C6: ='JAN 24'!D32 -> 4225
A7: 45323 | B7: Rent | C7: 8000
A8: 45323 | B8: SIP | C8: 2000
A9: 45323 | B9: Stocks | C9: 2000
A10: 45323 | B10: GOLD | C10: 300
A11: 45323 | B11: Hotstar | C11: 300
A12: 45323 | B12: Trust debt | C12: 150
A13: 45323 | B13: Shopping | C13: 500
A14: 45323 | B14: Expenses | C14: 3421
A15: 45352 | B15: Travel | C15: 1040
A16: 45352 | B16: Rent | C16: 8000
A17: 45352 | B17: SIP | C17: 2300
A18: 45352 | B18: Stocks | C18: 2000
... A40: 45413 | B40: Expenses | C40: 4650
A41: 45413 | B41: OTT | C41: =150 -> 150
A42: 45413 | B42: Total | C42: =SUM(C37:C41) -> 17100
A43: 45413 | B43: Salary | C43: 25000
A44: 45444 | B44: Stocks | C44: 2000
A45: 45444 | B45: SIP | C45: 2000
A46: 45444 | B46: Rent | C46: 8000
A47: 45444 | B47: Expenses | C47: 4237
A48: 45444 | B48: OTT | C48: 200
A49: 45444 | B49: GOLD | C49: 300
A50: 45658 | B50: GOLD | C50: 300
A51: 45658 | B51: SIP | C51: 2000
A52: 45658 | B52: Rent | C52: 7000
A53: 45658 | B53: Expenses | C53: 2590
A54: 45658 | B54: Travel | C54: =1200+1500 -> 2700
A55: 45658 | B55: Medical | C55: 500
A56: 45658 | B56: Stocks | C56: 3000
A57: 45658 | B57: Recharge | C57: 620
A58: 45658 | B58: GYM | C58: 600
A59: 45689 | B59: GOLD | C59: 300
A60: 45689 | B60: SIP | C60: 2000
A61: 45689 | B61: ETF | C61: 500
...

Sheet JAN 24
A1: Date | B1: Actual | C1: Budget | D1: Actual Cumm | E1: Budget Cumm
A2: 45292 | B2: =375+90 -> 465 | C2: 150 | D2: =B2 -> 465 | E2: =C2 -> 150
A3: 45293 | B3: 50 | C3: 150 | D3: =D2+B3 -> 515 | E3: =E2+150 -> 300
A4: 45294 | B4: 130 | C4: 150 | D4: =D3+B4 -> 645 | E4: =E3+150 -> 450
A5: 45295 | B5: 120 | C5: 150 | D5: =D4+B5 -> 765 | E5: =E4+150 -> 600
A6: 45296 | B6: 70 | C6: 150 | D6: =D5+B6 -> 835 | E6: =E5+150 -> 750
A7: 45297 | B7: 85 | C7: 150 | D7: =D6+B7 -> 920 | E7: =E6+150 -> 900
A8: 45298 | B8: =245+30+30+20 -> 325 | C8: 150 | D8: =D7+B8 -> 1245 | E8: =E7+150 -> 1050
A9: 45299 | B9: =250+30 -> 280 | C9: 150 | D9: =D8+B9 -> 1525 | E9: =E8+150 -> 1200
A10: 45300 | B10: 110 | C10: 150 | D10: =D9+B10 -> 1635 | E10: =E9+150 -> 1350
A11: 45301 | B11: 145 | C11: 150 | D11: =D10+B11 -> 1780 | E11: =E10+150 -> 1500
A12: 45302 | B12: 50 | C12: 150 | D12: =D11+B12 -> 1830 | E12: =E11+150 -> 1650
A13: 45303 | C13: 150 | D13: =D12+B13 -> 1830 | E13: =E12+150 -> 1800
A14: 45304 | C14: 150 | D14: =D13+B14 -> 1830 | E14: =E13+150 -> 1950
A15: 45305 | C15: 150 | D15: =D14+B15 -> 1830 | E15: =E14+150 -> 2100
A16: 45306 | C16: 150 | D16: =D15+B16 -> 1830 | E16: =E15+150 -> 2250
A17: 45307 | C17: 150 | D17: =D16+B17 -> 1830 | E17: =E16+150 -> 2400
A18: 45308 | B18: 110 | C18: 150 | D18: =D17+B18 -> 1940 | E18: =E17+150 -> 2550
A19: 45309 | B19: =85+40+15 -> 140 | C19: 150 | D19: =D18+B19 -> 2080 | E19: =E18+150 -> 2700
A20: 45310 | B20: 50 | C20: 150 | D20: =D19+B20 -> 2130 | E20: =E19+150 -> 2850
A21: 45311 | B21: =50+15 -> 65 | C21: 150 | D21: =D20+B21 -> 2195 | E21: =E20+150 -> 3000
A22: 45312 | B22: =115+40+15 -> 170 | C22: 150 | D22: =D21+B22 -> 2365 | E22: =E21+150 -> 3150
A23: 45313 | B23: 50 | C23: 150 | D23: =D22+B23 -> 2415 | E23: =E22+150 -> 3300
A24: 45314 | B24: 115 | C24: 150 | D24: =D23+B24 -> 2530 | E24: =E23+150 -> 3450
A25: 45315 | B25: 150 | C25: 150 | D25: =D24+B25 -> 2680 | E25: =E24+150 -> 3600
A26: 45316 | B26: 50 | C26: 150 | D26: =D25+B26 -> 2730 | E26: =E25+150 -> 3750
A27: 45317 | B27: =800+70+60+120 -> 1050 | C27: 150 | D27: =D26+B27 -> 3780 | E27: =E26+150 -> 3900
A28: 45318 | B28: 85 | C28: 150 | D28: =D27+B28 -> 3865 | E28: =E27+150 -> 4050
A29: 45319 | B29: 120 | C29: 150 | D29: =D28+B29 -> 3985 | E29: =E28+150 -> 4200
A30: 45320 | B30: 110 | C30: 150 | D30: =D29+B30 -> 4095 | E30: =E29+150 -> 4350
A31: 45321 | B31: 50 | C31: 150 | D31: =D30+B31 -> 4145 | E31: =E30+150 -> 4500
A32: 45322 | B32: 80 | C32: 150 | D32: =D31+B32 -> 4225 | E32: =E31+150 -> 4650
A33: 45323 | B33: 120 | C33: 150 | D33: 120 | E33: 150
A34: 45324 | B34: 50 | C34: 150 | D34: 170 | E34: 300
A35: 45325 | B35: 95 | C35: 150 | D35: 265 | E35: 450
A36: 45326 | B36: 270 | C36: 150 | D36: 535 | E36: 600
A37: 45327 | B37: 110 | C37: 150 | D37: 645 | E37: 750
A38: 45328 | B38: 100 | C38: 150 | D38: 745 | E38: 900
A39: 45329 | B39: 50 | C39: 150 | D39: 795 | E39: 1050
A40: 45330 | B40: 110 | C40: 150 | D40: 905 | E40: 1200
...

Sheet Sheet2
A1: emo emily
A2: venus afrodita
A3: angryamaon
A4: angelcruz
A5: thepaug
A6: jimenithahot
A7: cietra
A8: mr entertainer
A9: secretsfilmed
A10: nysdel
A11: ellie pink
